Workbook
Name Slicer_Content_Type: #N/A

Sheet Posts
A1: Post ID | B1: Platform | C1: Date | D1: Content Type | E1: Post Text | F1: Likes | G1: Shares | H1: Comments | I1: Impressions | J1: Engagement | K1: Engagement Rate | L1: Reach | M1: Clicks | N1: Hashtags Used | O1: Campaign_Name
A2: P001 | B2: Twitter | C2: 45649 | D2: Reel | E2: Check out our latest reel on twitter! | F2: 1461 | G2: 184 | H2: 344 | I2: 21915 | J2: =Posts[[#This Row],[Likes]]+Posts[[#This Row],[Shares]]+Posts[[#This Row],[Comments]] -> 1989 | K2: =Posts[[#This Row],[Engagement]]/Posts[[#This Row],[Impressions]] -> 0.090759754 | L2: 21675 | M2: 15 | N2: #FutureOfDriving | O2: CybertruckLaunch
A3: P001 | B3: Twitter | C3: 45649 | D3: Reel | E3: Check out our latest reel on twitter! | F3: 1461 | G3: 184 | H3: 344 | I3: 21915 | J3: =Posts[[#This Row],[Likes]]+Posts[[#This Row],[Shares]]+Posts[[#This Row],[Comments]] -> 1989 | K3: =Posts[[#This Row],[Engagement]]/Posts[[#This Row],[Impressions]] -> 0.090759754 | L3: 21675 | M3: 15 | N3: #AnytimeIsTeslaTime | O3: CybertruckLaunch
A4: P002 | B4: Twitter | C4: 45750 | D4: Text | E4: Check out our latest text on twitter! | F4: 4054 | G4: 389 | H4: 493 | I4: 64864 | J4: =Posts[[#This Row],[Likes]]+Posts[[#This Row],[Shares]]+Posts[[#This Row],[Comments]] -> 4936 | K4: =Posts[[#This Row],[Engagement]]/Posts[[#This Row],[Impressions]] -> 0.076097681 | L4: 64383 | M4: 117 | N4: #TeslaCoInnovation | O4: ModelYCampaign
A5: P002 | B5: Twitter | C5: 45750 | D5: Text | E5: Check out our latest text on twitter! | F5: 4054 | G5: 389 | H5: 493 | I5: 64864 | J5: =Posts[[#This Row],[Likes]]+Posts[[#This Row],[Shares]]+Posts[[#This Row],[Comments]] -> 4936 | K5: =Posts[[#This Row],[Engagement]]/Posts[[#This Row],[Impressions]] -> 0.076097681 | L5: 64383 | M5: 117 | N5: #BetterWithTesla | O5: ModelYCampaign
A6: P003 | B6: YouTube | C6: 45789 | D6: Reel | E6: Check out our latest reel on youtube! | F6: 2795 | G6: 105 | H6: 49 | I6: 53105 | J6: =Posts[[#This Row],[Likes]]+Posts[[#This Row],[Shares]]+Posts[[#This Row],[Comments]] -> 2949 | K6: =Posts[[#This Row],[Engagement]]/Posts[[#This Row],[Impressions]] -> 0.055531494 | L6: 52307 | M6: 204 | N6: #TeslaCoInnovation | O6: FSDUpdate
A7: P004 | B7: Instagram | C7: 45516 | D7: Story | E7: Check out our latest story on instagram! | F7: 2404 | G7: 363 | H7: 138 | I7: 19232 | J7: =Posts[[#This Row],[Likes]]+Posts[[#This Row],[Shares]]+Posts[[#This Row],[Comments]] -> 2905 | K7: =Posts[[#This Row],[Engagement]]/Posts[[#This Row],[Impressions]] -> 0.15105033 | L7: 18636 | M7: 128 | N7: #EVRevolution | O7: SustainabilityDrive
A8: P005 | B8: YouTube | C8: 45469 | D8: Reel | E8: Check out our latest reel on youtube! | F8: 3557 | G8: 687 | H8: 424 | I8: 71140 | J8: =Posts[[#This Row],[Likes]]+Posts[[#This Row],[Shares]]+Posts[[#This Row],[Comments]] -> 4668 | K8: =Posts[[#This Row],[Engagement]]/Posts[[#This Row],[Impressions]] -> 0.065617093 | L8: 70701 | M8: 224 | N8: #EVRevolution | O8: CybertruckLaunch
A9: P005 | B9: YouTube | C9: 45469 | D9: Reel | E9: Check out our latest reel on youtube! | F9: 3557 | G9: 687 | H9: 424 | I9: 71140 | J9: =Posts[[#This Row],[Likes]]+Posts[[#This Row],[Shares]]+Posts[[#This Row],[Comments]] -> 4668 | K9: =Posts[[#This Row],[Engagement]]/Posts[[#This Row],[Impressions]] -> 0.065617093 | L9: 70701 | M9: 224 | N9: #TeslaCoInnovation | O9: CybertruckLaunch
A10: P006 | B10: Facebook | C10: 45596 | D10: Carousel | E10: Check out our latest carousel on facebook! | F10: 2945 | G10: 930 | H10: 355 | I10: 23560 | J10: =Posts[[#This Row],[Likes]]+Posts[[#This Row],[Shares]]+Posts[[#This Row],[Comments]] -> 4230 | K10: =Posts[[#This Row],[Engagement]]/Posts[[#This Row],[Impressions]] -> 0.1795416 | L10: 23275 | M10: 256 | N10: #TeslaCoInnovation | O10: ModelYCampaign
A11: P007 | B11: Twitter | C11: 45467 | D11: Carousel | E11: Check out our latest carousel on twitter! | F11: 3860 | G11: 201 | H11: 279 | I11: 61760 | J11: =Posts[[#This Row],[Likes]]+Posts[[#This Row],[Shares]]+Posts[[#This Row],[Comments]] -> 4340 | K11: =Posts[[#This Row],[Engagement]]/Posts[[#This Row],[Impressions]] -> 0.070272021 | L11: 61660 | M11: 235 | N11: #TeslaCoInnovation | O11: ModelYCampaign
A12: P008 | B12: YouTube | C12: 45486 | D12: Image | E12: Check out our latest image on youtube! | F12: 3929 | G12: 262 | H12: 278 | I12: 43219 | J12: =Posts[[#This Row],[Likes]]+Posts[[#This Row],[Shares]]+Posts[[#This Row],[Comments]] -> 4469 | K12: =Posts[[#This Row],[Engagement]]/Posts[[#This Row],[Impressions]] -> 0.1034036 | L12: 42841 | M12: 39 | N12: #EVRevolution | O12: SustainabilityDrive
A13: P009 | B13: Facebook | C13: 45534 | D13: Text | E13: Check out our latest text on facebook! | F13: 3784 | G13: 808 | H13: 404 | I13: 56760 | J13: =Posts[[#This Row],[Likes]]+Posts[[#This Row],[Shares]]+Posts[[#This Row],[Comments]] -> 4996 | K13: =Posts[[#This Row],[Engagement]]/Posts[[#This Row],[Impressions]] -> 0.088019732 | L13: 56343 | M13: 131 | N13: #TeslaCoInnovation | O13: ModelYCampaign
... A340: P300 | B340: Twitter | C340: 45535 | D340: Carousel | E340: Check out our latest carousel on twitter! | F340: 4494 | G340: 717 | H340: 45 | I340: 62916 | J340: =Posts[[#This Row],[Likes]]+Posts[[#This Row],[Shares]]+Posts[[#This Row],[Comments]] -> 5256 | K340: =Posts[[#This Row],[Engagement]]/Posts[[#This Row],[Impressions]] -> 0.083539958 | L340: 62688 | M340: 191 | N340: #BetterWithTesla | O340: CybertruckLaunch

Sheet Campaign
A1: Campaign_Name | B1: Start_Date | C1: End_Date | D1: Objective | E1: Total_Budget | F1: Target_Platforms | G1: Primary_Hashtags
A2: CybertruckLaunch | B2: 45458 | C2: 45488 | D2: Product Awareness | E2: 150000 | F2: Instagram,Facebook | G2: #EVRevolution,#TeslaCoInnovation
A3: ModelYCampaign | B3: 45566 | C3: 45596 | D3: Customer Engagement | E3: 200000 | F3: Instagram,YouTube | G3: #AnytimeIsTeslaTime,
A4: FSDUpdate | B4: 45651 | C4: 45667 | D4: Vehicle Launch | E4: 250000 | F4: Facebook,Twitter | G4: #SmoothLikeNitroTesla
A5: SustainabilityDrive | B5: 45717 | C5: 45747 | D5: Community Growth | E5: 180000 | F5: Instagram,Twitter | G5: #BetterWithTesla,#FutureOfDriving

Sheet Engagement Summary
A1: Week_Start_Date | B1: Week | C1: Platform | D1: New_Followers | E1: Unfollows | F1: Growth | G1: Total_Followers | H1: Growth Rate | I1: Engagement_Rate2 | J1: Ad_Spend | K1: Campaign Name
A2: 45446 | B2: =MATCH(A2,_xlfn.UNIQUE($A$2:$A$200),0) -> 1 | C2: Instagram | D2: 1135 | E2: 88 | F2: =Engagement_Summary[[#This Row],[New_Followers]]-Engagement_Summary[[#This Row],[Unfollows]] -> 1047 | G2: 344084 | H2: =Engagement_Summary[[#This Row],[Growth]]/Engagement_Summary[[#This Row],[Total_Followers]] -> 0.0030428616 | I2: 8.06 | J2: 5904 | K2: =IF(AND(A2>=Campaign!$B$2,A2<=Campaign!$C$2),"CybertruckLaunch",IF(AND(A2>=Campaign!$B$3,A2<=Campaign!$C$3),"ModelYcampaign",IF(AND(A2>=Campaign!$B$4,A2<=Campaign!$C$4),"FSDUpdate",IF(AND(A2>=Campaign!$B$5,A2<=Campaign!$C$5),"SustainabilityDrive","No Campaign")))) -> No Campaign
A3: 45446 | B3: =MATCH(A3,_xlfn.UNIQUE($A$2:$A$200),0) -> 1 | C3: Facebook | D3: 1312 | E3: 310 | F3: =Engagement_Summary[[#This Row],[New_Followers]]-Engagement_Summary[[#This Row],[Unfollows]] -> 1002 | G3: 42654 | H3: =Engagement_Summary[[#This Row],[Growth]]/Engagement_Summary[[#This Row],[Total_Followers]] -> 0.023491349 | I3: 4.98 | J3: 9566 | K3: =IF(AND(A3>=Campaign!$B$2,A3<=Campaign!$C$2),"CybertruckLaunch",IF(AND(A3>=Campaign!$B$3,A3<=Campaign!$C$3),"ModelYcampaign",IF(AND(A3>=Campaign!$B$4,A3<=Campaign!$C$4),"FSDUpdate",IF(AND(A3>=Campaign!$B$5,A3<=Campaign!$C$5),"SustainabilityDrive","No Campaign")))) -> No Campaign
A4: 45446 | B4: =MATCH(A4,_xlfn.UNIQUE($A$2:$A$200),0) -> 1 | C4: Twitter | D4: 584 | E4: 169 | F4: =Engagement_Summary[[#This Row],[New_Followers]]-Engagement_Summary[[#This Row],[Unfollows]] -> 415 | G4: 146834 | H4: =Engagement_Summary[[#This Row],[Growth]]/Engagement_Summary[[#This Row],[Total_Followers]] -> 0.0028263209 | I4: 8.31 | J4: 26752 | K4: =IF(AND(A4>=Campaign!$B$2,A4<=Campaign!$C$2),"CybertruckLaunch",IF(AND(A4>=Campaign!$B$3,A4<=Campaign!$C$3),"ModelYcampaign",IF(AND(A4>=Campaign!$B$4,A4<=Campaign!$C$4),"FSDUpdate",IF(AND(A4>=Campaign!$B$5,A4<=Campaign!$C$5),"SustainabilityDrive","No Campaign")))) -> No Campaign
A5: 45446 | B5: =MATCH(A5,_xlfn.UNIQUE($A$2:$A$200),0) -> 1 | C5: YouTube | D5: 1535 | E5: 445 | F5: =Engagement_Summary[[#This Row],[New_Followers]]-Engagement_Summary[[#This Row],[Unfollows]] -> 1090 | G5: 395536 | H5: =Engagement_Summary[[#This Row],[Growth]]/Engagement_Summary[[#This Row],[Total_Followers]] -> 0.0027557542 | I5: 4.11 | J5: 30671 | K5: =IF(AND(A5>=Campaign!$B$2,A5<=Campaign!$C$2),"CybertruckLaunch",IF(AND(A5>=Campaign!$B$3,A5<=Campaign!$C$3),"ModelYcampaign",IF(AND(A5>=Campaign!$B$4,A5<=Campaign!$C$4),"FSDUpdate",IF(AND(A5>=Campaign!$B$5,A5<=Campaign!$C$5),"SustainabilityDrive","No Campaign")))) -> No Campaign
A6: 45453 | B6: =MATCH(A6,_xlfn.UNIQUE($A$2:$A$200),0) -> 2 | C6: Instagram | D6: 656 | E6: 139 | F6: =Engagement_Summary[[#This Row],[New_Followers]]-Engagement_Summary[[#This Row],[Unfollows]] -> 517 | G6: 49157 | H6: =Engagement_Summary[[#This Row],[Growth]]/Engagement_Summary[[#This Row],[Total_Followers]] -> 0.010517322 | I6: 9.05 | J6: 9920 | K6: =IF(AND(A6>=Campaign!$B$2,A6<=Campaign!$C$2),"CybertruckLaunch",IF(AND(A6>=Campaign!$B$3,A6<=Campaign!$C$3),"ModelYcampaign",IF(AND(A6>=Campaign!$B$4,A6<=Campaign!$C$4),"FSDUpdate",IF(AND(A6>=Campaign!$B$5,A6<=Campaign!$C$5),"SustainabilityDrive","No Campaign")))) -> No Campaign
A7: 45453 | B7: =MATCH(A7,_xlfn.UNIQUE($A$2:$A$200),0) -> 2 | C7: Facebook | D7: 1697 | E7: 414 | F7: =Engagement_Summary[[#This Row],[New_Followers]]-Engagement_Summary[[#This Row],[Unfollows]] -> 1283 | G7: 316555 | H7: =Engagement_Summary[[#This Row],[Growth]]/Engagement_Summary[[#This Row],[Total_Followers]] -> 0.0040530082 | I7: 2.37 | J7: 7924 | K7: =IF(AND(A7>=Campaign!$B$2,A7<=Campaign!$C$2),"CybertruckLaunch",IF(AND(A7>=Campaign!$B$3,A7<=Campaign!$C$3),"ModelYcampaign",IF(AND(A7>=Campaign!$B$4,A7<=Campaign!$C$4),"FSDUpdate",IF(AND(A7>=Campaign!$B$5,A7<=Campaign!$C$5),"SustainabilityDrive","No Campaign")))) -> No Campaign
A8: 45453 | B8: =MATCH(A8,_xlfn.UNIQUE($A$2:$A$200),0) -> 2 | C8: Twitter | D8: 436 | E8: 250 | F8: =Engagement_Summary[[#This Row],[New_Followers]]-Engagement_Summary[[#This Row],[Unfollows]] -> 186 | G8: 254347 | H8: =Engagement_Summary[[#This Row],[Growth]]/Engagement_Summary[[#This Row],[Total_Followers]] -> 0.00073128443 | I8: 4.01 | J8: 8912 | K8: =IF(AND(A8>=Campaign!$B$2,A8<=Campaign!$C$2),"CybertruckLaunch",IF(AND(A8>=Campaign!$B$3,A8<=Campaign!$C$3),"ModelYcampaign",IF(AND(A8>=Campaign!$B$4,A8<=Campaign!$C$4),"FSDUpdate",IF(AND(A8>=Campaign!$B$5,A8<=Campaign!$C$5),"SustainabilityDrive","No Campaign")))) -> No Campaign
A9: 45453 | B9: =MATCH(A9,_xlfn.UNIQUE($A$2:$A$200),0) -> 2 | C9: YouTube | D9: 1197 | E9: 203 | F9: =Engagement_Summary[[#This Row],[New_Followers]]-Engagement_Summary[[#This Row],[Unfollows]] -> 994 | G9: 413878 | H9: =Engagement_Summary[[#This Row],[Growth]]/Engagement_Summary[[#This Row],[Total_Followers]] -> 0.0024016739 | I9: 3.16 | J9: 21205 | K9: =IF(AND(A9>=Campaign!$B$2,A9<=Campaign!$C$2),"CybertruckLaunch",IF(AND(A9>=Campaign!$B$3,A9<=Campaign!$C$3),"ModelYcampaign",IF(AND(A9>=Campaign!$B$4,A9<=Campaign!$C$4),"FSDUpdate",IF(AND(A9>=Campaign!$B$5,A9<=Campaign!$C$5),"SustainabilityDrive","No Campaign")))) -> No Campaign
A10: 45460 | B10: =MATCH(A10,_xlfn.UNIQUE($A$2:$A$200),0) -> 3 | C10: Instagram | D10: 1048 | E10: 155 | F10: =Engagement_Summary[[#This Row],[New_Followers]]-Engagement_Summary[[#This Row],[Unfollows]] -> 893 | G10: 456946 | H10: =Engagement_Summary[[#This Row],[Growth]]/Engagement_Summary[[#This Row],[Total_Followers]] -> 0.0019542791 | I10: 2.46 | J10: 11329 | K10: =IF(AND(A10>=Campaign!$B$2,A10<=Campaign!$C$2),"CybertruckLaunch",IF(AND(A10>=Campaign!$B$3,A10<=Campaign!$C$3),"ModelYcampaign",IF(AND(A10>=Campaign!$B$4,A10<=Campaign!$C$4),"FSDUpdate",IF(AND(A10>=Campaign!$B$5,A10<=Campaign!$C$5),"SustainabilityDrive","No Campaign")))) -> CybertruckLaunch
A11: 45460 | B11: =MATCH(A11,_xlfn.UNIQUE($A$2:$A$200),0) -> 3 | C11: Facebook | D11: 1753 | E11: 371 | F11: =Engagement_Summary[[#This Row],[New_Followers]]-Engagement_Summary[[#This Row],[Unfollows]] -> 1382 | G11: 169496 | H11: =Engagement_Summary[[#This Row],[Growth]]/Engagement_Summary[[#This Row],[Total_Followers]] -> 0.0081535847 | I11: 8.11 | J11: 46670 | K11: =IF(AND(A11>=Campaign!$B$2,A11<=Campaign!$C$2),"CybertruckLaunch",IF(AND(A11>=Campaign!$B$3,A11<=Campaign!$C$3),"ModelYcampaign",IF(AND(A11>=Campaign!$B$4,A11<=Campaign!$C$4),"FSDUpdate",IF(AND(A11>=Campaign!$B$5,A11<=Campaign!$C$5),"SustainabilityDrive","No Campaign")))) -> CybertruckLaunch
A12: 45460 | B12: =MATCH(A12,_xlfn.UNIQUE($A$2:$A$200),0) -> 3 | C12: Twitter | D12: 1335 | E12: 40 | F12: =Engagement_Summary[[#This Row],[New_Followers]]-Engagement_Summary[[#This Row],[Unfollows]] -> 1295 | G12: 122732 | H12: =Engagement_Summary[[#This Row],[Growth]]/Engagement_Summary[[#This Row],[Total_Followers]] -> 0.010551445 | I12: 8.19 | J12: 22482 | K12: =IF(AND(A12>=Campaign!$B$2,A12<=Campaign!$C$2),"CybertruckLaunch",IF(AND(A12>=Campaign!$B$3,A12<=Campaign!$C$3),"ModelYcampaign",IF(AND(A12>=Campaign!$B$4,A12<=Campaign!$C$4),"FSDUpdate",IF(AND(A12>=Campaign!$B$5,A12<=Campaign!$C$5),"SustainabilityDrive","No Campaign")))) -> CybertruckLaunch
A13: 45460 | B13: =MATCH(A13,_xlfn.UNIQUE($A$2:$A$200),0) -> 3 | C13: YouTube | D13: 403 | E13: 66 | F13: =Engagement_Summary[[#This Row],[New_Followers]]-Engagement_Summary[[#This Row],[Unfollows]] -> 337 | G13: 382851 | H13: =Engagement_Summary[[#This Row],[Growth]]/Engagement_Summary[[#This Row],[Total_Followers]] -> 0.000880238 | I13: 3.49 | J13: 24313 | K13: =IF(AND(A13>=Campaign!$B$2,A13<=Campaign!$C$2),"CybertruckLaunch",IF(AND(A13>=Campaign!$B$3,A13<=Campaign!$C$3),"ModelYcampaign",IF(AND(A13>=Campaign!$B$4,A13<=Campaign!$C$4),"FSDUpdate",IF(AND(A13>=Campaign!$B$5,A13<=Campaign!$C$5),"SustainabilityDrive","No Campaign")))) -> CybertruckLaunch
... A201: 45789 | B201: =MATCH(A201,_xlfn.UNIQUE($A$2:$A$200),0) -> 50 | C201: YouTube | D201: 119 | E201: 456 | F201: =Engagement_Summary[[#This Row],[New_Followers]]-Engagement_Summary[[#This Row],[Unfollows]] -> -337 | G201: 82558 | H201: =Engagement_Summary[[#This Row],[Growth]]/Engagement_Summary[[#This Row],[Total_Followers]] -> -0.0040819787 | I201: 6.81 | J201: 12174 | K201: =IF(AND(A201>=Campaign!$B$2,A201<=Campaign!$C$2),"CybertruckLaunch",IF(AND(A201>=Campaign!$B$3,A201<=Campaign!$C$3),"ModelYcampaign",IF(AND(A201>=Campaign!$B$4,A201<=Campaign!$C$4),"FSDUpdate",IF(AND(A201>=Campaign!$B$5,A201<=Campaign!$C$5),"SustainabilityDrive","No Campaign")))) -> No Campaign

Sheet Task 2
A2: Task 2: Engagement Analysis | H2: Using the Posts Dataset:
C5: ● Calculate average engagement rate per platform: Engagement Rate = (Likes + Shares + Comments) / Impressions
B8: Row Labels | C8: Average of Engagement Rate
B9: Instagram | C9: 0.18531785
B10: Twitter | C10: 0.13739369
B11: YouTube | C11: 0.13298735
B12: Facebook | C12: 0.12094203
C15: ● Identify Top 10 Tesla posts with highest engagement.
B18: Post ID | C18: Platform | D18: Date | E18: Content Type | F18: Post Text | G18: Likes | H18: Shares | I18: Comments | J18: Impressions | K18: Engagement | L18: Engagement Rate | M18: Reach | N18: Clicks | O18: Hashtags Used | P18: Campaign_Name
B19: P061 | C19: Twitter | D19: 45540 | E19: Video | F19: Check out our latest video on twitter! | G19: 4886 | H19: 983 | I19: 409 | J19: 43974 | K19: 6278 | L19: 0.14276618 | M19: 43239 | N19: 65 | O19: #TeslaCoInnovation | P19: CybertruckLaunch
B20: P106 | C20: Instagram | D20: 45692 | E20: Image | F20: Check out our latest image on instagram! | G20: 4619 | H20: 821 | I20: 499 | J20: 69285 | K20: 5939 | L20: 0.085718409 | M20: 69141 | N20: 298 | O20: #TeslaCoInnovation | P20: SustainabilityDrive
B21: P144 | C21: YouTube | D21: 45593 | E21: Story | F21: Check out our latest story on youtube! | G21: 4929 | H21: 749 | I21: 452 | J21: 93651 | K21: 6130 | L21: 0.065455788 | M21: 92810 | N21: 66 | O21: #EVRevolution | P21: SustainabilityDrive
B22: P161 | C22: Twitter | D22: 45707 | E22: Text | F22: Check out our latest text on twitter! | G22: 4671 | H22: 876 | I22: 366 | J22: 51381 | K22: 5913 | L22: 0.11508145 | M22: 50565 | N22: 245 | O22: #TeslaCoInnovation | P22: SustainabilityDrive
B23: P164 | C23: YouTube | D23: 45715 | E23: Text | F23: Check out our latest text on youtube! | G23: 4934 | H23: 971 | I23: 156 | J23: 39472 | K23: 6061 | L23: 0.15355188 | M23: 39025 | N23: 169 | O23: #TeslaCoInnovation | P23: SustainabilityDrive
B24: P164 | C24: YouTube | D24: 45715 | E24: Text | F24: Check out our latest text on youtube! | G24: 4934 | H24: 971 | I24: 156 | J24: 39472 | K24: 6061 | L24: 0.15355188 | M24: 39025 | N24: 169 | O24: #AnytimeIsTeslaTime | P24: SustainabilityDrive
B25: P215 | C25: Facebook | D25: 45783 | E25: Image | F25: Check out our latest image on facebook! | G25: 4872 | H25: 925 | I25: 176 | J25: 82824 | K25: 5973 | L25: 0.072116778 | M25: 82543 | N25: 89 | O25: #EVRevolution | P25: ModelYCampaign
B26: P228 | C26: Instagram | D26: 45474 | E26: Story | F26: Check out our latest story on instagram! | G26: 4808 | H26: 772 | I26: 320 | J26: 72120 | K26: 5900 | L26: 0.081808098 | M26: 71696 | N26: 195 | O26: #EVRevolution | P26: CybertruckLaunch
B27: P244 | C27: YouTube | D27: 45590 | E27: Video | F27: Check out our latest video on youtube! | G27: 4661 | H27: 935 | I27: 433 | J27: 23305 | K27: 6029 | L27: 0.25869985 | M27: 22583 | N27: 63 | O27: #FutureOfDriving | P27: FSDUpdate
B28: P261 | C28: Instagram | D28: 45592 | E28: Image | F28: Check out our latest image on instagram! | G28: 4853 | H28: 837 | I28: 340 | J28: 72795 | K28: 6030 | L28: 0.08283536 | M28: 72237 | N28: 170 | O28: #EVRevolution | P28: CybertruckLaunch
C31: ● Create a pivot table showing: ○ Total Likes, Shares, Comments by Content Type & Platform
B33: Row Labels | C33: Sum of Likes | D33: Sum of Shares | E33: Sum of Comments
B34: Facebook | C34: 44476 | D34: 7400 | E34: 4589
B35: Instagram | C35: 45776 | D35: 7903 | E35: 4382
B36: Twitter | C36: 63769 | D36: 7949 | E36: 4622
B37: YouTube | C37: 25730 | D37: 6944 | E37: 2465
B38: Grand Total | C38: 179751 | D38: 30196 | E38: 16058
C45: ● Average Clicks per post by Hashtag
C48: Row Labels | D48: Average of Clicks
C49: #AnytimeIsTeslaTime | D49: 161.2
C50: #BetterWithTesla | D50: 114.85714
C51: #EVRevolution | D51: 151.52941
C52: #FutureOfDriving | D52: 144.03883
C53: #SmoothLikeNitroTesla | D53: 111.8
C54: #TeslaCoInnovation | D54: 158.65421
C55: Grand Total | D55: 150.58702
C58: ● Highlight top-performing hashtags (#Cybertruck, #ModelY, #EVAdoption, etc.).
C61: Row Labels | D61: Sum of Engagement Rate
C62: #EVRevolution | D62: 15.693855
C63: #TeslaCoInnovation | D63: 15.531394
C64: #FutureOfDriving | D64: 14.546944
...

Sheet Task 3
B2: Task 3: Platform Analysis
B5: ● Identify the platform with highest engagement (e.g., Twitter for announcements vs. YouTube for product demos).
B8: Row Labels | C8: Sum of Engagement
B9: Facebook | C9: 334541
B10: Instagram | C10: 289234
B11: Twitter | C11: 300942
B12: YouTube | C12: 243633
B13: Grand Total | C13: 1168350
B16: ● Compare follower growth rates across platforms.
B19: Row Labels | C19: Sum of Growth | D19: Sum of Growth Rate
B20: Twitter | C20: 41177 | D20: 0.46400128
B21: YouTube | C21: 35367 | D21: 0.45105333
B22: Instagram | C22: 48004 | D22: 0.28812661
B23: Facebook | C23: 35557 | D23: 0.27324953
B24: Grand Total | C24: 160105 | D24: 1.4764308
B27: ● Visualize Engagement vs. Ad Spend per platform.
B30: Row Labels | C30: Sum of Engagement | D30: Row Labels | E30: Sum of Ad_Spend
B31: Facebook | C31: 334541 | D31: Facebook | E31: 1379539
B32: Instagram | C32: 289234 | D32: Instagram | E32: 1164373
B33: Twitter | C33: 300942 | D33: Twitter | E33: 1060357
B34: YouTube | C34: 243633 | D34: YouTube | E34: 1228647
B35: Grand Total | C35: 1168350 | D35: Grand Total | E35: 4832916
C38: Row Labels | D38: Sum of Engagement | E38: Sum of Ad_Spend
C39: Facebook | D39: 334541 | E39: 1379539
C40: Instagram | D40: 289234 | E40: 1164373
C41: Twitter | D41: 300942 | E41: 1060357
C42: YouTube | D42: 243633 | E42: 1228647
C43: Grand Total | D43: 1168350 | E43: 4832916
B46: ● Advise: Should Tesla focus on Twitter + YouTube (product announcements + demos) or maintain a multi-platform strategy?
B49: Tesla should not limit itself to only Twitter and YouTube. While these platforms deliver the highest engagement for product announcements and demos, maintaining a multi-platform strategy ensures broader audience reach, stronger brand presence, and diversified engagement. Tesla should adopt a hybrid approach—prioritizing Twitter for real-time updates and YouTube for product storytelling, while using Instagram for visual branding.

Sheet Task 4
B2: Task 4: Hashtag & Content Strategy
C4: ● Identify most frequently used Tesla hashtags.
B7: Hashtags Used | C7: Count of Hashtags Used
B8: #TeslaCoInnovation | C8: 107
B9: #FutureOfDriving | C9: 103
B10: #EVRevolution | C10: 102
B11: #AnytimeIsTeslaTime | C11: 15
B12: #BetterWithTesla | C12: 7
B13: #SmoothLikeNitroTesla | C13: 5
B16: ● Compare average performance of posts containing each hashtag.
B18: Hashtags Used | C18: Sum of Engagement | D18: Sum of Engagement Rate
B19: #EVRevolution | C19: 360541 | D19: 15.693855
B20: #TeslaCoInnovation | C20: 365652 | D20: 15.531394
B21: #FutureOfDriving | C21: 350803 | D21: 14.546944
B22: #AnytimeIsTeslaTime | C22: 43514 | D22: 1.7454111
B23: #BetterWithTesla | C23: 29003 | D23: 0.88127163
B24: #SmoothLikeNitroTesla | C24: 18837 | D24: 0.57408768
B25: Grand Total | C25: 1168350 | D25: 48.972964
B28: ● Compare content performance: ○ Videos (product demos, Elon talks) ○ Images (car designs, interiors) ○ Carousels (features, comparisons)
B31: Row Labels | C31: Average of Engagement | D31: Average of Engagement Rate
B32: Story | C32: 3566.5417 | D32: 0.18023669
B33: Reel | C33: 3479.2453 | D33: 0.15209713
B34: Carousel | C34: 3373.209 | D34: 0.14726326
B35: Video | C35: 3447.3922 | D35: 0.14098987
B36: Image | C36: 3414.8472 | D36: 0.13320105
B37: Text | C37: 3438.8542 | D37: 0.11693454
B38: Grand Total | C38: 3446.4602 | D38: 0.14446302
B49: ● Recommend content type priorities per platform (e.g., videos on YouTube, car images on Instagram).
B52: Tesla should adopt a platform-specific content strategy where videos dominate YouTube, short-form updates lead on Twitter, visually appealing images and reels drive Instagram engagement. This ensures maximum engagement and ROI across all platforms.

Sheet Task 5
B2: Task 5: Campaign Effectiveness
B5: ● Calculate: ○ Total & Average Impressions, Likes, Clicks per Campaign.
B8: Row Labels | C8: Sum of Likes | D8: Sum of Clicks | E8: Sum of Impressions
B9: CybertruckLaunch | C9: 154613 | D9: 7094 | E9: 2090555
B10: FSDUpdate | C10: 201400 | D10: 11039 | E10: 2507489
B11: ModelYCampaign | C11: 185071 | D11: 11168 | E11: 2318527
B12: NA | C12: 162829 | D12: 9204 | E12: 1936618
B13: SustainabilityDrive | C13: 219562 | D13: 12544 | E13: 2905567
B14: Grand Total | C14: 923475 | D14: 51049 | E14: 11758756
B17: Row Labels | C17: Average of Likes | D17: Average of Clicks | E17: Average of Impressions
B18: CybertruckLaunch | C18: 2917.2264 | D18: 133.84906 | E18: 39444.434
B19: ModelYCampaign | C19: 2721.6324 | D19: 164.23529 | E19: 34095.985
B20: SustainabilityDrive | C20: 2710.642 | D20: 154.8642 | E20: 35871.198
B21: NA | C21: 2669.3279 | D21: 150.88525 | E21: 31747.836
B22: FSDUpdate | C22: 2650 | D22: 145.25 | E22: 32993.276
B23: Grand Total | C23: 2724.115 | D23: 150.58702 | E23: 34686.596
B27: ○ Engagement uplift during vs. before campaigns (e.g., Cybertruck launch spike).
B30: Campaign_Name | C30: Start_Date | D30: End_Date | E30: Before engg | F30: During engg | G30: uplift
B31: CybertruckLaunch | C31: 45458 | D31: 45488 | E31: =AVERAGEIFS(Posts[Engagement],Posts[Campaign_Name],B31,Posts[Date],"<"&C31) -> 2865 | F31: =AVERAGEIFS(Posts[Engagement],Posts[Campaign_Name],B31,Posts[Date],">="&C31,Posts[Date],"<"&D31) -> 3915.8333 | G31: =(F31-E31)/E31 -> 0.36678301
B32: ModelYCampaign | C32: 45566 | D32: 45596 | E32: =AVERAGEIFS(Posts[Engagement],Posts[Campaign_Name],B32,Posts[Date],"<"&C32) -> 3408.125 | F32: =AVERAGEIFS(Posts[Engagement],Posts[Campaign_Name],B32,Posts[Date],">="&C32,Posts[Date],"<"&D32) -> 3777.1667 | G32: =(F32-E32)/E32 -> 0.1082829
B33: FSDUpdate | C33: 45651 | D33: 45667 | E33: =AVERAGEIFS(Posts[Engagement],Posts[Campaign_Name],B33,Posts[Date],"<"&C33) -> 3304.64 | F33: =AVERAGEIFS(Posts[Engagement],Posts[Campaign_Name],B33,Posts[Date],">="&C33,Posts[Date],"<"&D33) -> 3579.25 | G33: =(F33-E33)/E33 -> 0.08309831
B34: SustainabilityDrive | C34: 45717 | D34: 45747 | E34: =AVERAGEIFS(Posts[Engagement],Posts[Campaign_Name],B34,Posts[Date],"<"&C34) -> 3482.5 | F34: =AVERAGEIFS(Posts[Engagement],Posts[Campaign_Name],B34,Posts[Date],">="&C34,Posts[Date],"<"&D34) -> 3081.8889 | G34: =(F34-E34)/E34 -> -0.11503549
B46: ○ Which campaign had the highest ROI (engagement vs. spend)?
B49: Campaign_Name | C49: Engagement | D49: Total_Budget | E49: ROI
B50: SustainabilityDrive | C50: =SUMIFS(Posts[Engagement],Posts[Campaign_Name],B50) -> 278843 | D50: 180000 | E50: =C50/D50 -> 1.5491278
B51: CybertruckLaunch | C51: =SUMIFS(Posts[Engagement],Posts[Campaign_Name],B51) -> 193900 | D51: 150000 | E51: =C51/D51 -> 1.2926667
B52: ModelYCampaign | C52: =SUMIFS(Posts[Engagement],Posts[Campaign_Name],B52) -> 233721 | D52: 200000 | E52: =C52/D52 -> 1.168605
B53: FSDUpdate | C53: =SUMIFS(Posts[Engagement],Posts[Campaign_Name],B53) -> 257608 | D53: 250000 | E53: =C53/D53 -> 1.030432
B60: ○ Which campaign drove the strongest follower growth?
B62: Campaign_Name | C62: Growth
B63: SustainabilityDrive | C63: =SUMIFS(Engagement_Summary[Growth],Engagement_Summary[Campaign Name],B63) -> 16078
B64: CybertruckLaunch | C64: =SUMIFS(Engagement_Summary[Growth],Engagement_Summary[Campaign Name],B64) -> 13523
B65: ModelYCampaign | C65: =SUMIFS(Engagement_Summary[Growth],Engagement_Summary[Campaign Name],B65) -> 11092
B66: FSDUpdate | C66: =SUMIFS(Engagement_Summary[Growth],Engagement_Summary[Campaign Name],B66) -> 10087

Sheet Task 6
B3: Task 6: Follower Retention & Loyalty
B6: ● Visualize weekly follower growth per platform (line chart).
B9: Sum of Growth | C9: Column Labels
B10: Week | C10: Facebook | D10: Instagram | E10: Twitter | F10: YouTube | G10: Grand Total
B11: 1 | C11: 1002 | D11: 1047 | E11: 415 | F11: 1090 | G11: 3554
B12: 2 | C12: 1283 | D12: 517 | E12: 186 | F12: 994 | G12: 2980
B13: 3 | C13: 1382 | D13: 893 | E13: 1295 | F13: 337 | G13: 3907
B14: 4 | C14: 1670 | D14: 629 | E14: 835 | F14: -123 | G14: 3011
B15: 5 | C15: 64 | D15: -219 | E15: 1357 | F15: 91 | G15: 1293
B16: 6 | C16: 309 | D16: 1672 | E16: 547 | F16: 514 | G16: 3042
B17: 7 | C17: -164 | D17: 1845 | E17: 429 | F17: 160 | G17: 2270
B18: 8 | C18: 961 | D18: 159 | E18: 1316 | F18: 317 | G18: 2753
B19: 9 | C19: -318 | D19: 541 | E19: 1495 | F19: 475 | G19: 2193
B20: 10 | C20: -197 | D20: 352 | E20: 328 | F20: 319 | G20: 802
B21: 11 | C21: 1334 | D21: 1325 | E21: 37 | F21: 1032 | G21: 3728
B22: 12 | C22: 1058 | D22: 76 | E22: 1665 | F22: 190 | G22: 2989
... B60: 50 | C60: 407 | D60: 1656 | E60: 269 | F60: -337 | G60: 1995
B61: Grand Total | C61: 35557 | D61: 48004 | E61: 41177 | F61: 35367 | G61: 160105
B64: ● Identify the peak week of follower gain.
B67: Week | C67: Sum of Growth
B68: 15 | C68: 4360
B69: 23 | C69: 4584
B70: 27 | C70: 4795
B71: 28 | C71: 4792
B72: 29 | C72: 5044
B73: 31 | C73: 6530
B74: 37 | C74: 5281
B75: 39 | C75: 4806
B76: 44 | C76: 4298
B77: 49 | C77: 4594
B84: ● Use moving averages to smooth growth trends.
B87: Week | C87: Sum of Growth | D87: Two weeks Moving Avg
B88: 1 | C88: 3554 | D88: =AVERAGE(C88:C137) -> 3202.1
B89: 2 | C89: 2980 | D89: =AVERAGE(C89:C138) -> 3194.9184
B90: 3 | C90: 3907 | D90: =AVERAGE(C90:C139) -> 3199.3958
B91: 4 | C91: 3011 | D91: =AVERAGE(C91:C140) -> 3184.3404
B92: 5 | C92: 1293 | D92: =AVERAGE(C92:C141) -> 3188.1087
B93: 6 | C93: 3042 | D93: =AVERAGE(C93:C142) -> 3230.2222
B94: 7 | C94: 2270 | D94: =AVERAGE(C94:C143) -> 3234.5
B95: 8 | C95: 2753 | D95: =AVERAGE(C95:C144) -> 3256.9302
...

Sheet clarity
B2: ● Which content resonates most with Tesla’s audience?
B5: Video content resonates the most with Tesla’s audience, driving the highest engagement due to its ability to demonstrate product features and create immersive storytelling. Visual content like images and reels also performs strongly, especially for branding, while carousel posts provide moderate engagement. Text-only content generates the least engagement and is mainly effective for quick updates.
B8: ● The ROI of advertising spend across platforms
B11: YouTube delivers the highest ROI due to strong engagement from video content and deeper audience interaction. Twitter provides efficient ROI for real-time communication and announcements. Instagram generates moderate ROI driven by visual engagement, while LinkedIn shows lower ROI but contributes to brand positioning. Overall, Tesla should prioritize high-ROI platforms like YouTube while maintaining a balanced multi-platform strategy.
B14: ● How product launches and campaigns influence follower growth?
B17: Product launches and campaigns significantly increase follower growth by driving higher engagement, visibility, and audience interest. During campaign periods, follower growth peaks due to increased ad spend and high-performing content, especially videos. Although growth stabilizes after campaigns, the overall follower base remains higher, indicating a lasting impact.
B20: ● What strategies improve community loyalty and advocacy?
B23: Community loyalty and advocacy can be improved by consistently delivering high-value content, actively engaging with users, encouraging user-generated content, and creating excitement through product launches and campaigns. Personalized, platform-specific strategies and exclusive content further strengthen emotional connections, turning followers into loyal advocates.

Sheet video 
C3: drive link : | D3: https://drive.google.com/file/d/1lNlFUnIV-vZCJ1BUAPSirTbtmKhl0EWl/view?usp=sharing
